Workbook
Name Slicer_Country: #N/A
Name Slicer_Rating_Category: #N/A
Name Slicer_Release_year: #N/A
Name Slicer_Type: #N/A

Sheet Movie vs Shows
A3: Row Labels | B3: Count of Show_id
A4: Movie | B4: 0.97240991
A5: TV Show | B5: 0.02759009

Sheet Country-wise content
A3: Row Labels | B3: Count of Title
A4: United States | B4: 1846
A5: India | B5: 875
A6: United Kingdom | B6: 183
A7: Canada | B7: 107
A8: Spain | B8: 91
A9: Egypt | B9: 89
A10: Nigeria | B10: 88
A11: Japan | B11: 83
A12: Turkey | B12: 79
A13: Indonesia | B13: 76

Sheet Release_Trend
A3: Row Labels | B3: Count of Title
A4: 2021 | B4: 161
A5: 2012 | B5: 163
A6: 2013 | B6: 197
A7: 2014 | B7: 242
A8: 2015 | B8: 349
A9: 2020 | B9: 442
A10: 2019 | B10: 519
A11: 2016 | B11: 576
A12: 2018 | B12: 647
A13: 2017 | B13: 656

Sheet Rating_Distribution
A3: Row Labels | B3: Count of Show_id
A4: Adult | B4: 0.48817568
A5: Family | B5: 0.15578078
A6: Kids | B6: 0.029091592
A7: Not Rated | B7: 0.011448949
A8: Teen | B8: 0.315503

Sheet Dashboard
D1: Netflix Content Distribution
A2: ='Top country'!A4 -> United States
A6: =COUNTA(Table1[Show_id]) -> 5328
A10: =COUNTIF(Table1[Type],"Movie") -> 5181
A14: =COUNTIF(Table1[Type],"Tv Show") -> 147
A18: =COUNTA(_xlfn.UNIQUE(Table1[Country])) -> 603
A22: =ROUND(AVERAGE(Table1[Release_year]),0) -> 2013

Sheet Top country
A3: Row Labels | B3: Count of Show_id
A4: United States | B4: 1846

Sheet Netflix_Dataset
A1: Show_id | B1: Type | C1: Title | D1: Director | E1: Cast | F1: Country | G1: Date_added | H1: Year_Added | I1: Release_year | J1: Content age(years) | K1: Rating | L1: Rating Category | M1: Recommendation | N1: Duration | O1: Duration Category | P1: Listed_in
A2: s8 | B2: Movie | C2: Sankofa | D2: Haile Gerima | E2: Kofi Ghanaba, Oyafunmike Ogunlano, Alexandra Duah, Nick Medley, Mutabaruka, Afemo Omilami, Reggie Carter, Mzuri | F2: United States, Ghana, Burkina Faso, United Kingdom, Germany, Ethiopia | G2: September 1, 2021 | H2: 2021 | I2: 1993 | J2: =YEAR(TODAY())-Table1[[#This Row],[Release_year]] -> 33 | K2: TV-MA | L2: =_xlfn.XLOOKUP(Table1[[#This Row],[Rating]],Ratings!A$2:A$15,Ratings!B$2:B$15) -> Adult | M2: =_xlfn.XLOOKUP(Table1[[#This Row],[Rating Category]],Recommendation!A$2:A$6,Recommendation!B$2:B$6) -> Restricted | N2: 125 | O2: {=_xlfn.IFS(Table1[[#This Row],[Duration]]<90,"Short",Table1[[#This Row],[Duration]]<180,"Medium",Table1[[#This Row],[Duration]]<=240,"Long",TRUE,"Seasons")} -> Medium | P2: Dramas, Independent Movies, International Movies
A3: s9 | B3: TV Show | C3: The Great British Baking Show | D3: Andy Devonshire | E3: Mel Giedroyc, Sue Perkins, Mary Berry, Paul Hollywood | F3: United Kingdom | G3: September 24, 2021 | H3: 2021 | I3: 2021 | J3: =YEAR(TODAY())-Table1[[#This Row],[Release_year]] -> 5 | K3: TV-14 | L3: =_xlfn.XLOOKUP(Table1[[#This Row],[Rating]],Ratings!A$2:A$15,Ratings!B$2:B$15) -> Teen | M3: =_xlfn.XLOOKUP(Table1[[#This Row],[Rating Category]],Recommendation!A$2:A$6,Recommendation!B$2:B$6) -> Guidance | N3: 9 Seasons | O3: {=_xlfn.IFS(Table1[[#This Row],[Duration]]<90,"Short",Table1[[#This Row],[Duration]]<180,"Medium",Table1[[#This Row],[Duration]]<=240,"Long",TRUE,"Seasons")} -> Seasons | P3: British TV Shows, Reality TV
A4: s10 | B4: Movie | C4: The Starling | D4: Theodore Melfi | E4: Melissa McCarthy, Chris O'Dowd, Kevin Kline, Timothy Olyphant, Daveed Diggs, Skyler Gisondo, Laura Harrier, Rosalind Chao, Kimberly Quinn, Loretta Devine, Ravi Kapoor | F4: United States | G4: September 24, 2021 | H4: 2021 | I4: 2021 | J4: =YEAR(TODAY())-Table1[[#This Row],[Release_year]] -> 5 | K4: PG-13 | L4: =_xlfn.XLOOKUP(Table1[[#This Row],[Rating]],Ratings!A$2:A$15,Ratings!B$2:B$15) -> Teen | M4: =_xlfn.XLOOKUP(Table1[[#This Row],[Rating Category]],Recommendation!A$2:A$6,Recommendation!B$2:B$6) -> Guidance | N4: 104 | O4: {=_xlfn.IFS(Table1[[#This Row],[Duration]]<90,"Short",Table1[[#This Row],[Duration]]<180,"Medium",Table1[[#This Row],[Duration]]<=240,"Long",TRUE,"Seasons")} -> Medium | P4: Comedies, Dramas
A5: s13 | B5: Movie | C5: Je Suis Karl | D5: Christian Schwochow | E5: Luna Wedler, Jannis Niewhner, Milan Peschel, Edin Hasanovi, Anna Fialov, Marlon Boess, Victor Boccard, Fleur Geffrier, Aziz Dyab, Mlanie Fouch, Elizaveta Maximov | F5: Germany, Czech Republic | G5: September 23, 2021 | H5: 2021 | I5: 2021 | J5: =YEAR(TODAY())-Table1[[#This Row],[Release_year]] -> 5 | K5: TV-MA | L5: =_xlfn.XLOOKUP(Table1[[#This Row],[Rating]],Ratings!A$2:A$15,Ratings!B$2:B$15) -> Adult | M5: =_xlfn.XLOOKUP(Table1[[#This Row],[Rating Category]],Recommendation!A$2:A$6,Recommendation!B$2:B$6) -> Restricted | N5: 127 | O5: {=_xlfn.IFS(Table1[[#This Row],[Duration]]<90,"Short",Table1[[#This Row],[Duration]]<180,"Medium",Table1[[#This Row],[Duration]]<=240,"Long",TRUE,"Seasons")} -> Medium | P5: Dramas, International Movies
A6: s25 | B6: Movie | C6: Jeans | D6: S. Shankar | E6: Prashanth, Aishwarya Rai Bachchan, Sri Lakshmi, Nassar | F6: India | G6: September 21, 2021 | H6: 2021 | I6: 1998 | J6: =YEAR(TODAY())-Table1[[#This Row],[Release_year]] -> 28 | K6: TV-14 | L6: =_xlfn.XLOOKUP(Table1[[#This Row],[Rating]],Ratings!A$2:A$15,Ratings!B$2:B$15) -> Teen | M6: =_xlfn.XLOOKUP(Table1[[#This Row],[Rating Category]],Recommendation!A$2:A$6,Recommendation!B$2:B$6) -> Guidance | N6: 166 | O6: {=_xlfn.IFS(Table1[[#This Row],[Duration]]<90,"Short",Table1[[#This Row],[Duration]]<180,"Medium",Table1[[#This Row],[Duration]]<=240,"Long",TRUE,"Seasons")} -> Medium | P6: Comedies, International Movies, Romantic Movies
A7: s28 | B7: Movie | C7: Grown Ups | D7: Dennis Dugan | E7: Adam Sandler, Kevin James, Chris Rock, David Spade, Rob Schneider, Salma Hayek, Maria Bello, Maya Rudolph, Colin Quinn, Tim Meadows, Joyce Van Patten | F7: United States | G7: September 20, 2021 | H7: 2021 | I7: 2010 | J7: =YEAR(TODAY())-Table1[[#This Row],[Release_year]] -> 16 | K7: PG-13 | L7: =_xlfn.XLOOKUP(Table1[[#This Row],[Rating]],Ratings!A$2:A$15,Ratings!B$2:B$15) -> Teen | M7: =_xlfn.XLOOKUP(Table1[[#This Row],[Rating Category]],Recommendation!A$2:A$6,Recommendation!B$2:B$6) -> Guidance | N7: 103 | O7: {=_xlfn.IFS(Table1[[#This Row],[Duration]]<90,"Short",Table1[[#This Row],[Duration]]<180,"Medium",Table1[[#This Row],[Duration]]<=240,"Long",TRUE,"Seasons")} -> Medium | P7: Comedies
A8: s29 | B8: Movie | C8: Dark Skies | D8: Scott Stewart | E8: Keri Russell, Josh Hamilton, J.K. Simmons, Dakota Goyo, Kadan Rockett, L.J. Benet, Rich Hutchman, Myndy Crist, Annie Thurman, Jake Brennan | F8: United States | G8: September 19, 2021 | H8: 2021 | I8: 2013 | J8: =YEAR(TODAY())-Table1[[#This Row],[Release_year]] -> 13 | K8: PG-13 | L8: =_xlfn.XLOOKUP(Table1[[#This Row],[Rating]],Ratings!A$2:A$15,Ratings!B$2:B$15) -> Teen | M8: =_xlfn.XLOOKUP(Table1[[#This Row],[Rating Category]],Recommendation!A$2:A$6,Recommendation!B$2:B$6) -> Guidance | N8: 97 | O8: {=_xlfn.IFS(Table1[[#This Row],[Duration]]<90,"Short",Table1[[#This Row],[Duration]]<180,"Medium",Table1[[#This Row],[Duration]]<=240,"Long",TRUE,"Seasons")} -> Medium | P8: Horror Movies, Sci-Fi & Fantasy
A9: s30 | B9: Movie | C9: Paranoia | D9: Robert Luketic | E9: Liam Hemsworth, Gary Oldman, Amber Heard, Harrison Ford, Lucas Till, Embeth Davidtz, Julian McMahon, Josh Holloway, Richard Dreyfuss, Angela Sarafyan | F9: United States, India, France | G9: September 19, 2021 | H9: 2021 | I9: 2013 | J9: =YEAR(TODAY())-Table1[[#This Row],[Release_year]] -> 13 | K9: PG-13 | L9: =_xlfn.XLOOKUP(Table1[[#This Row],[Rating]],Ratings!A$2:A$15,Ratings!B$2:B$15) -> Teen | M9: =_xlfn.XLOOKUP(Table1[[#This Row],[Rating Category]],Recommendation!A$2:A$6,Recommendation!B$2:B$6) -> Guidance | N9: 106 | O9: {=_xlfn.IFS(Table1[[#This Row],[Duration]]<90,"Short",Table1[[#This Row],[Duration]]<180,"Medium",Table1[[#This Row],[Duration]]<=240,"Long",TRUE,"Seasons")} -> Medium | P9: Thrillers
A10: s39 | B10: Movie | C10: Birth of the Dragon | D10: George Nolfi | E10: Billy Magnussen, Ron Yuan, Qu Jingjing, Terry Chen, Vanness Wu, Jin Xing, Philip Ng, Xia Yu, Yu Xia | F10: China, Canada, United States | G10: September 16, 2021 | H10: 2021 | I10: 2017 | J10: =YEAR(TODAY())-Table1[[#This Row],[Release_year]] -> 9 | K10: PG-13 | L10: =_xlfn.XLOOKUP(Table1[[#This Row],[Rating]],Ratings!A$2:A$15,Ratings!B$2:B$15) -> Teen | M10: =_xlfn.XLOOKUP(Table1[[#This Row],[Rating Category]],Recommendation!A$2:A$6,Recommendation!B$2:B$6) -> Guidance | N10: 96 | O10: {=_xlfn.IFS(Table1[[#This Row],[Duration]]<90,"Short",Table1[[#This Row],[Duration]]<180,"Medium",Table1[[#This Row],[Duration]]<=240,"Long",TRUE,"Seasons")} -> Medium | P10: Action & Adventure, Dramas
A11: s42 | B11: Movie | C11: Jaws | D11: Steven Spielberg | E11: Roy Scheider, Robert Shaw, Richard Dreyfuss, Lorraine Gary, Murray Hamilton, Carl Gottlieb, Jeffrey Kramer, Susan Backlinie, Jonathan Filley, Ted Grossman | F11: United States | G11: September 16, 2021 | H11: 2021 | I11: 1975 | J11: =YEAR(TODAY())-Table1[[#This Row],[Release_year]] -> 51 | K11: PG | L11: =_xlfn.XLOOKUP(Table1[[#This Row],[Rating]],Ratings!A$2:A$15,Ratings!B$2:B$15) -> Family | M11: =_xlfn.XLOOKUP(Table1[[#This Row],[Rating Category]],Recommendation!A$2:A$6,Recommendation!B$2:B$6) -> Guidance | N11: 124 | O11: {=_xlfn.IFS(Table1[[#This Row],[Duration]]<90,"Short",Table1[[#This Row],[Duration]]<180,"Medium",Table1[[#This Row],[Duration]]<=240,"Long",TRUE,"Seasons")} -> Medium | P11: Action & Adventure, Classic Movies, Dramas
A12: s43 | B12: Movie | C12: Jaws 2 | D12: Jeannot Szwarc | E12: Roy Scheider, Lorraine Gary, Murray Hamilton, Joseph Mascolo, Jeffrey Kramer, Collin Wilcox Paxton, Ann Dusenberry, Mark Gruner, Barry Coe, Susan French | F12: United States | G12: September 16, 2021 | H12: 2021 | I12: 1978 | J12: =YEAR(TODAY())-Table1[[#This Row],[Release_year]] -> 48 | K12: PG | L12: =_xlfn.XLOOKUP(Table1[[#This Row],[Rating]],Ratings!A$2:A$15,Ratings!B$2:B$15) -> Family | M12: =_xlfn.XLOOKUP(Table1[[#This Row],[Rating Category]],Recommendation!A$2:A$6,Recommendation!B$2:B$6) -> Guidance | N12: 116 | O12: {=_xlfn.IFS(Table1[[#This Row],[Duration]]<90,"Short",Table1[[#This Row],[Duration]]<180,"Medium",Table1[[#This Row],[Duration]]<=240,"Long",TRUE,"Seasons")} -> Medium | P12: Dramas, Horror Movies, Thrillers
A13: s44 | B13: Movie | C13: Jaws 3 | D13: Joe Alves | E13: Dennis Quaid, Bess Armstrong, Simon MacCorkindale, Louis Gossett Jr., John Putch, Lea Thompson, P.H. Moriarty, Dan Blasko, Liz Morris, Lisa Maurer | F13: United States | G13: September 16, 2021 | H13: 2021 | I13: 1983 | J13: =YEAR(TODAY())-Table1[[#This Row],[Release_year]] -> 43 | K13: PG | L13: =_xlfn.XLOOKUP(Table1[[#This Row],[Rating]],Ratings!A$2:A$15,Ratings!B$2:B$15) -> Family | M13: =_xlfn.XLOOKUP(Table1[[#This Row],[Rating Category]],Recommendation!A$2:A$6,Recommendation!B$2:B$6) -> Guidance | N13: 98 | O13: {=_xlfn.IFS(Table1[[#This Row],[Duration]]<90,"Short",Table1[[#This Row],[Duration]]<180,"Medium",Table1[[#This Row],[Duration]]<=240,"Long",TRUE,"Seasons")} -> Medium | P13: Action & Adventure, Horror Movies, Thrillers
A14: s45 | B14: Movie | C14: Jaws: The Revenge | D14: Joseph Sargent | E14: Lorraine Gary, Lance Guest, Mario Van Peebles, Karen Young, Michael Caine, Judith Barsi, Mitchell Anderson, Lynn Whitfield | F14: United States | G14: September 16, 2021 | H14: 2021 | I14: 1987 | J14: =YEAR(TODAY())-Table1[[#This Row],[Release_year]] -> 39 | K14: PG-13 | L14: =_xlfn.XLOOKUP(Table1[[#This Row],[Rating]],Ratings!A$2:A$15,Ratings!B$2:B$15) -> Teen | M14: =_xlfn.XLOOKUP(Table1[[#This Row],[Rating Category]],Recommendation!A$2:A$6,Recommendation!B$2:B$6) -> Guidance | N14: 91 | O14: {=_xlfn.IFS(Table1[[#This Row],[Duration]]<90,"Short",Table1[[#This Row],[Duration]]<180,"Medium",Table1[[#This Row],[Duration]]<=240,"Long",TRUE,"Seasons")} -> Medium | P14: Action & Adventure, Horror Movies, Thrillers
A15: s47 | B15: Movie | C15: Safe House | D15: Daniel Espinosa | E15: Denzel Washington, Ryan Reynolds, Vera Farmiga, Brendan Gleeson, Sam Shepard, Rubn Blades, Nora Arnezeder, Robert Patrick, Liam Cunningham, Joel Kinnaman | F15: South Africa, United States, Japan | G15: September 16, 2021 | H15: 2021 | I15: 2012 | J15: =YEAR(TODAY())-Table1[[#This Row],[Release_year]] -> 14 | K15: R | L15: =_xlfn.XLOOKUP(Table1[[#This Row],[Rating]],Ratings!A$2:A$15,Ratings!B$2:B$15) -> Adult | M15: =_xlfn.XLOOKUP(Table1[[#This Row],[Rating Category]],Recommendation!A$2:A$6,Recommendation!B$2:B$6) -> Restricted | N15: 115 | O15: {=_xlfn.IFS(Table1[[#This Row],[Duration]]<90,"Short",Table1[[#This Row],[Duration]]<180,"Medium",Table1[[#This Row],[Duration]]<=240,"Long",TRUE,"Seasons")} -> Medium | P15: Action & Adventure
... A93: s196 | B93: Movie | C93: EMI: Liya Hai To Chukana Padega | D93: Saurabh Kabra | E93: Sanjay Dutt, Arjun Rampal, Malaika Arora, Aashish Chaudhary, Neha Uberoi, Urmila Matondkar, Manoj Joshi, Daya Shankar Pandey, Pushkar Jog, Kulbhushan Kharbanda | F93: India | G93: August 27, 2021 | H93: 2021 | I93: 2008 | J93: =YEAR(TODAY())-Table1[[#This Row],[Release_year]] -> 18 | K93: TV-14 | L93: =_xlfn.XLOOKUP(Table1[[#This Row],[Rating]],Ratings!A$2:A$15,Ratings!B$2:B$15) -> Teen | M93: =_xlfn.XLOOKUP(Table1[[#This Row],[Rating Category]],Recommendation!A$2:A$6,Recommendation!B$2:B$6) -> Guidance | N93: 128 | O93: {=_xlfn.IFS(Table1[[#This Row],[Duration]]<90,"Short",Table1[[#This Row],[Duration]]<180,"Medium",Table1[[#This Row],[Duration]]<=240,"Long",TRUE,"Seasons")} -> Medium | P93: Comedies, Dramas, International Movies
A94: s199 | B94: TV Show | C94: King of Boys: The Return of the King | D94: Kemi Adetiba | E94: Sola Sobowale, Toni Tones, Richard Mofe-Damijo, Efa Iwara, Titi Kuti, Tobechukwu "iLLbliss" Ejiofor, Remilekun "Reminisce" Safaru, Charles "Charly Boy" Oputa, Nse Ikpe-Etim, Keppy Ekpenyong Bassey, Bimbo Manuel, Akin Lewis, Lord Frank, Osas Ighodaro, Taiwo Ajai-Lycett, Paul Sambo | F94: Nigeria | G94: August 27, 2021 | H94: 2021 | I94: 2021 | J94: =YEAR(TODAY())-Table1[[#This Row],[Release_year]] -> 5 | K94: TV-MA | L94: =_xlfn.XLOOKUP(Table1[[#This Row],[Rating]],Ratings!A$2:A$15,Ratings!B$2:B$15) -> Adult | M94: =_xlfn.XLOOKUP(Table1[[#This Row],[Rating Category]],Recommendation!A$2:A$6,Recommendation!B$2:B$6) -> Restricted | N94: 1 Season | O94: {=_xlfn.IFS(Table1[[#This Row],[Duration]]<90,"Short",Table1[[#This Row],[Duration]]<180,"Medium",Table1[[#This Row],[Duration]]<=240,"Long",TRUE,"Seasons")} -> Seasons | P94: Crime TV Shows, International TV Shows, TV Dramas
A95: s200 | B95: Movie | C95: Koi Aap Sa | D95: Partho Mitra | E95: Aftab Shivdasani, Natassha, Dipannita Sharma, Himanshu Mallik, Vaidya Advai, Pushy Anand, Shama Deshpande, Rajendra Gupta | F95: India | G95: August 27, 2021 | H95: 2021 | I95: 2006 | J95: =YEAR(TODAY())-Table1[[#This Row],[Release_year]] -> 20 | K95: TV-14 | L95: =_xlfn.XLOOKUP(Table1[[#This Row],[Rating]],Ratings!A$2:A$15,Ratings!B$2:B$15) -> Teen | M95: =_xlfn.XLOOKUP(Table1[[#This Row],[Rating Category]],Recommendation!A$2:A$6,Recommendation!B$2:B$6) -> Guidance | N95: 135 | O95: {=_xlfn.IFS(Table1[[#This Row],[Duration]]<90,"Short",Table1[[#This Row],[Duration]]<180,"Medium",Table1[[#This Row],[Duration]]<=240,"Long",TRUE,"Seasons")} -> Medium | P95: Comedies, Dramas, International Movies
A96: s201 | B96: Movie | C96: Krishna Cottage | D96: Santram Varma | E96: Sohail Khan, Isha Koppikar, Natassha, Rati Agnihotri, Vrajesh Hirjee, Divya Palat, Hiten Tejwani, Rajendranath Zutshi | F96: India | G96: August 27, 2021 | H96: 2021 | I96: 2004 | J96: =YEAR(TODAY())-Table1[[#This Row],[Release_year]] -> 22 | K96: TV-14 | L96: =_xlfn.XLOOKUP(Table1[[#This Row],[Rating]],Ratings!A$2:A$15,Ratings!B$2:B$15) -> Teen | M96: =_xlfn.XLOOKUP(Table1[[#This Row],[Rating Category]],Recommendation!A$2:A$6,Recommendation!B$2:B$6) -> Guidance | N96: 124 | O96: {=_xlfn.IFS(Table1[[#This Row],[Duration]]<90,"Short",Table1[[#This Row],[Duration]]<180,"Medium",Table1[[#This Row],[Duration]]<=240,"Long",TRUE,"Seasons")} -> Medium | P96: Action & Adventure, Horror Movies, International Movies
A97: s202 | B97: Movie | C97: Kucch To Hai | D97: Anil V. Kumar, Anurag Basu | E97: Tusshar Kapoor, Esha Deol, Natassha, Vrajesh Hirjee, Kusumit Sana, Rishi Kapoor, Moon Moon Sen, Johny Lever, Ashay Chitre, Jeetendra | F97: India | G97: August 27, 2021 | H97: 2021 | I97: 2003 | J97: =YEAR(TODAY())-Table1[[#This Row],[Release_year]] -> 23 | K97: TV-14 | L97: =_xlfn.XLOOKUP(Table1[[#This Row],[Rating]],Ratings!A$2:A$15,Ratings!B$2:B$15) -> Teen | M97: =_xlfn.XLOOKUP(Table1[[#This Row],[Rating Category]],Recommendation!A$2:A$6,Recommendation!B$2:B$6) -> Guidance | N97: 136 | O97: {=_xlfn.IFS(Table1[[#This Row],[Duration]]<90,"Short",Table1[[#This Row],[Duration]]<180,"Medium",Table1[[#This Row],[Duration]]<=240,"Long",TRUE,"Seasons")} -> Medium | P97: Dramas, International Movies, Thrillers
A98: s203 | B98: Movie | C98: Kyaa Kool Hai Hum | D98: Sangeeth Sivan | E98: Tusshar Kapoor, Riteish Deshmukh, Isha Koppikar, Neha Dhupia, Anupam Kher, Jay Sean | F98: India | G98: August 27, 2021 | H98: 2021 | I98: 2005 | J98: =YEAR(TODAY())-Table1[[#This Row],[Release_year]] -> 21 | K98: TV-MA | L98: =_xlfn.XLOOKUP(Table1[[#This Row],[Rating]],Ratings!A$2:A$15,Ratings!B$2:B$15) -> Adult | M98: =_xlfn.XLOOKUP(Table1[[#This Row],[Rating Category]],Recommendation!A$2:A$6,Recommendation!B$2:B$6) -> Restricted | N98: 165 | O98: {=_xlfn.IFS(Table1[[#This Row],[Duration]]<90,"Short",Table1[[#This Row],[Duration]]<180,"Medium",Table1[[#This Row],[Duration]]<=240,"Long",TRUE,"Seasons")} -> Medium | P98: Comedies, International Movies, Music & Musicals
A99: s204 | B99: Movie | C99: Kyaa Kool Hain Hum 3 | D99: Umesh Ghadge | E99: Tusshar Kapoor, Aftab Shivdasani, Krishna Abhishek, Mandana Karimi, Shakti Kapoor, Darshan Jariwala, Sushmita Mukherjee, Meghna Naidu, Anand Kumar, Claudia Ciesla | F99: India | G99: August 27, 2021 | H99: 2021 | I99: 2016 | J99: =YEAR(TODAY())-Table1[[#This Row],[Release_year]] -> 10 | K99: TV-MA | L99: =_xlfn.XLOOKUP(Table1[[#This Row],[Rating]],Ratings!A$2:A$15,Ratings!B$2:B$15) -> Adult | M99: =_xlfn.XLOOKUP(Table1[[#This Row],[Rating Category]],Recommendation!A$2:A$6,Recommendation!B$2:B$6) -> Restricted | N99: 124 | O99: {=_xlfn.IFS(Table1[[#This Row],[Duration]]<90,"Short",Table1[[#This Row],[Duration]]<180,"Medium",Table1[[#This Row],[Duration]]<=240,"Long",TRUE,"Seasons")} -> Medium | P99: Comedies, International Movies
A100: s205 | B100: Movie | C100: Kyaa Super Kool Hain Hum | D100: Sachin Yardi | E100: Tusshar Kapoor, Riteish Deshmukh, Anupam Kher, Rohit Shetty, Neha Sharma, Chunky Pandey, Sarah-Jane Dias, Razak Khan, Kavin Dave | F100: India | G100: August 27, 2021 | H100: 2021 | I100: 2012 | J100: =YEAR(TODAY())-Table1[[#This Row],[Release_year]] -> 14 | K100: TV-MA | L100: =_xlfn.XLOOKUP(Table1[[#This Row],[Rating]],Ratings!A$2:A$15,Ratings!B$2:B$15) -> Adult | M100: =_xlfn.XLOOKUP(Table1[[#This Row],[Rating Category]],Recommendation!A$2:A$6,Recommendation!B$2:B$6) -> Restricted | N100: 136 | O100: {=_xlfn.IFS(Table1[[#This Row],[Duration]]<90,"Short",Table1[[#This Row],[Duration]]<180,"Medium",Table1[[#This Row],[Duration]]<=240,"Long",TRUE,"Seasons")} -> Medium | P100: Comedies, International Movies
A101: s206 | B101: Movie | C101: Kyo Kii... Main Jhuth Nahin Bolta | D101: David Dhawan | E101: Govinda, Sushmita Sen, Rambha, Anupam Kher, Satish Kaushik, Sharad Kapoor, Kiran Kumar, Mohnish Bahl | F101: India | G101: August 27, 2021 | H101: 2021 | I101: 2001 | J101: =YEAR(TODAY())-Table1[[#This Row],[Release_year]] -> 25 | K101: TV-14 | L101: =_xlfn.XLOOKUP(Table1[[#This Row],[Rating]],Ratings!A$2:A$15,Ratings!B$2:B$15) -> Teen | M101: =_xlfn.XLOOKUP(Table1[[#This Row],[Rating Category]],Recommendation!A$2:A$6,Recommendation!B$2:B$6) -> Guidance | N101: 150 | O101: {=_xlfn.IFS(Table1[[#This Row],[Duration]]<90,"Short",Table1[[#This Row],[Duration]]<180,"Medium",Table1[[#This Row],[Duration]]<=240,"Long",TRUE,"Seasons")} -> Medium | P101: Comedies, International Movies, Sci-Fi & Fantasy
A102: s207 | B102: Movie | C102: LSD: Love, Sex Aur Dhokha | D102: Dibakar Banerjee | E102: Nushrat Bharucha, Anshuman Jha, Neha Chauhan, Rajkummar Rao, Arya Banerjee, Amit Sial, Herry Tangri | F102: India | G102: August 27, 2021 | H102: 2021 | I102: 2010 | J102: =YEAR(TODAY())-Table1[[#This Row],[Release_year]] -> 16 | K102: TV-MA | L102: =_xlfn.XLOOKUP(Table1[[#This Row],[Rating]],Ratings!A$2:A$15,Ratings!B$2:B$15) -> Adult | M102: =_xlfn.XLOOKUP(Table1[[#This Row],[Rating Category]],Recommendation!A$2:A$6,Recommendation!B$2:B$6) -> Restricted | N102: 112 | O102: {=_xlfn.IFS(Table1[[#This Row],[Duration]]<90,"Short",Table1[[#This Row],[Duration]]<180,"Medium",Table1[[#This Row],[Duration]]<=240,"Long",TRUE,"Seasons")} -> Medium | P102: Dramas, Independent Movies, International Movies
A103: s208 | B103: Movie | C103: Mission Istaanbul: Darr Ke Aagey Jeet Hai | D103: Apoorva Lakhia | E103: Vivek Oberoi, Zayed Khan, Shriya Saran, Nikitin Dheer, Shabbir Ahluwalia, Sunil Shetty, Shweta Bhardwaj | F103: India | G103: August 27, 2021 | H103: 2021 | I103: 2008 | J103: =YEAR(TODAY())-Table1[[#This Row],[Release_year]] -> 18 | K103: TV-14 | L103: =_xlfn.XLOOKUP(Table1[[#This Row],[Rating]],Ratings!A$2:A$15,Ratings!B$2:B$15) -> Teen | M103: =_xlfn.XLOOKUP(Table1[[#This Row],[Rating Category]],Recommendation!A$2:A$6,Recommendation!B$2:B$6) -> Guidance | N103: 119 | O103: {=_xlfn.IFS(Table1[[#This Row],[Duration]]<90,"Short",Table1[[#This Row],[Duration]]<180,"Medium",Table1[[#This Row],[Duration]]<=240,"Long",TRUE,"Seasons")} -> Medium | P103: Action & Adventure, International Movies, Music & Musicals
A104: s209 | B104: Movie | C104: Once Upon a Time in Mumbaai | D104: Milan Luthria | E104: Ajay Devgn, Emraan Hashmi, Kangana Ranaut, Prachi Desai, Randeep Hooda, Naved Aslam, Asif Basra, Avtar Gill | F104: India | G104: August 27, 2021 | H104: 2021 | I104: 2010 | J104: =YEAR(TODAY())-Table1[[#This Row],[Release_year]] -> 16 | K104: TV-14 | L104: =_xlfn.XLOOKUP(Table1[[#This Row],[Rating]],Ratings!A$2:A$15,Ratings!B$2:B$15) -> Teen | M104: =_xlfn.XLOOKUP(Table1[[#This Row],[Rating Category]],Recommendation!A$2:A$6,Recommendation!B$2:B$6) -> Guidance | N104: 133 | O104: {=_xlfn.IFS(Table1[[#This Row],[Duration]]<90,"Short",Table1[[#This Row],[Duration]]<180,"Medium",Table1[[#This Row],[Duration]]<=240,"Long",TRUE,"Seasons")} -> Medium | P104: Dramas, International Movies, Music & Musicals
A105: s210 | B105: Movie | C105: Once Upon a Time in Mumbai Dobaara! | D105: Milan Luthria | E105: Akshay Kumar, Imran Khan, Sonakshi Sinha, Sonali Bendre, Sarfaraz Khan, Mahesh Manjrekar, Abhimanyu Singh, Kurush Deboo, Pitobash, Chetan Hansraj | F105: India | G105: August 27, 2021 | H105: 2021 | I105: 2013 | J105: =YEAR(TODAY())-Table1[[#This Row],[Release_year]] -> 13 | K105: TV-14 | L105: =_xlfn.XLOOKUP(Table1[[#This Row],[Rating]],Ratings!A$2:A$15,Ratings!B$2:B$15) -> Teen | M105: =_xlfn.XLOOKUP(Table1[[#This Row],[Rating Category]],Recommendation!A$2:A$6,Recommendation!B$2:B$6) -> Guidance | N105: 142 | O105: {=_xlfn.IFS(Table1[[#This Row],[Duration]]<90,"Short",Table1[[#This Row],[Duration]]<180,"Medium",Table1[[#This Row],[Duration]]<=240,"Long",TRUE,"Seasons")} -> Medium | P105: Dramas, International Movies, Music & Musicals
A106: s211 | B106: Movie | C106: Ragini MMS | D106: Pawan Kripalani | E106: Kainaz Motivala, Rajkummar Rao, Rajat Kaul, Janice, Shernaza, Mangala Ahire, Vinod Rawat | F106: India | G106: August 27, 2021 | H106: 2021 | I106: 2011 | J106: =YEAR(TODAY())-Table1[[#This Row],[Release_year]] -> 15 | K106: TV-MA | L106: =_xlfn.XLOOKUP(Table1[[#This Row],[Rating]],Ratings!A$2:A$15,Ratings!B$2:B$15) -> Adult | M106: =_xlfn.XLOOKUP(Table1[[#This Row],[Rating Category]],Recommendation!A$2:A$6,Recommendation!B$2:B$6) -> Restricted | N106: 93 | O106: {=_xlfn.IFS(Table1[[#This Row],[Duration]]<90,"Short",Table1[[#This Row],[Duration]]<180,"Medium",Table1[[#This Row],[Duration]]<=240,"Long",TRUE,"Seasons")} -> Medium | P106: Horror Movies, International Movies
... A121: s271 | B121: Movie | C121: Beckett | D121: Ferdinando Cito Filomarino | E121: John David Washington, Boyd Holbrook, Alicia Vikander, Vicky Krieps, Lena Kitsopoulou, Panos Koronis, Maria Votti | F121: Italy, Brazil, Greece | G121: August 13, 2021 | H121: 2021 | I121: 2021 | J121: =YEAR(TODAY())-Table1[[#This Row],[Release_year]] -> 5 | K121: TV-MA | L121: =_xlfn.XLOOKUP(Table1[[#This Row],[Rating]],Ratings!A$2:A$15,Ratings!B$2:B$15) -> Adult | M121: =_xlfn.XLOOKUP(Table1[[#This Row],[Rating Category]],Recommendation!A$2:A$6,Recommendation!B$2:B$6) -> Restricted | N121: 110 | O121: {=_xlfn.IFS(Table1[[#This Row],[Duration]]<90,"Short",Table1[[#This Row],[Duration]]<180,"Medium",Table1[[#This Row],[Duration]]<=240,"Long",TRUE,"Seasons")} -> Medium | P121: Action & Adventure
A122: s274 | B122: TV Show | C122: Gone for Good | D122: Juan Carlos Medina | E122: Finnegan Oldfield, Nicolas Duvauchelle, Guillaume Gouix, Garance Marillier, Nailia Harzoune | F122: France | G122: August 13, 2021 | H122: 2021 | I122: 2021 | J122: =YEAR(TODAY())-Table1[[#This Row],[Release_year]] -> 5 | K122: TV-MA | L122: =_xlfn.XLOOKUP(Table1[[#This Row],[Rating]],Ratings!A$2:A$15,Ratings!B$2:B$15) -> Adult | M122: =_xlfn.XLOOKUP(Table1[[#This Row],[Rating Category]],Recommendation!A$2:A$6,Recommendation!B$2:B$6) -> Restricted | N122: 1 Season | O122: {=_xlfn.IFS(Table1[[#This Row],[Duration]]<90,"Short",Table1[[#This Row],[Duration]]<180,"Medium",Table1[[#This Row],[Duration]]<=240,"Long",TRUE,"Seasons")} -> Seasons | P122: Crime TV Shows, International TV Shows, TV Dramas
A123: s277 | B123: TV Show | C123: Valeria | D123: Inma Torrente | E123: Diana Gmez, Silma Lpez, Paula Malia, Teresa Riott, Maxi Iglesias, Ibrahim Al Shami | F123: Spain | G123: August 13, 2021 | H123: 2021 | I123: 2021 | J123: =YEAR(TODAY())-Table1[[#This Row],[Release_year]] -> 5 | K123: TV-MA | L123: =_xlfn.XLOOKUP(Table1[[#This Row],[Rating]],Ratings!A$2:A$15,Ratings!B$2:B$15) -> Adult | M123: =_xlfn.XLOOKUP(Table1[[#This Row],[Rating Category]],Recommendation!A$2:A$6,Recommendation!B$2:B$6) -> Restricted | N123: 2 Seasons | O123: {=_xlfn.IFS(Table1[[#This Row],[Duration]]<90,"Short",Table1[[#This Row],[Duration]]<180,"Medium",Table1[[#This Row],[Duration]]<=240,"Long",TRUE,"Seasons")} -> Seasons | P123: International TV Shows, Romantic TV Shows, Spanish-Language TV Shows
A124: s279 | B124: Movie | C124: Lokillo: Nothing's the Same | D124: Julin Gaviria | E124: Lokillo Florez | F124: Colombia | G124: August 12, 2021 | H124: 2021 | I124: 2021 | J124: =YEAR(TODAY())-Table1[[#This Row],[Release_year]] -> 5 | K124: TV-MA | L124: =_xlfn.XLOOKUP(Table1[[#This Row],[Rating]],Ratings!A$2:A$15,Ratings!B$2:B$15) -> Adult | M124: =_xlfn.XLOOKUP(Table1[[#This Row],[Rating Category]],Recommendation!A$2:A$6,Recommendation!B$2:B$6) -> Restricted | N124: 64 | O124: {=_xlfn.IFS(Table1[[#This Row],[Duration]]<90,"Short",Table1[[#This Row],[Duration]]<180,"Medium",Table1[[#This Row],[Duration]]<=240,"Long",TRUE,"Seasons")} -> Short | P124: Stand-Up Comedy
A125: s280 | B125: Movie | C125: Monster Hunter: Legends of the Guild | D125: Steven Yamamoto | E125: Ben Rausch, Erica Lindbeck, Dante Basco, Brando Eaton, Stephen Kramer Glickman, Caroline Caliston, G.K. Bowes, Dan McCoy | F125: United States, Japan | G125: August 12, 2021 | H125: 2021 | I125: 2021 | J125: =YEAR(TODAY())-Table1[[#This Row],[Release_year]] -> 5 | K125: TV-PG | L125: =_xlfn.XLOOKUP(Table1[[#This Row],[Rating]],Ratings!A$2:A$15,Ratings!B$2:B$15) -> Family | M125: =_xlfn.XLOOKUP(Table1[[#This Row],[Rating Category]],Recommendation!A$2:A$6,Recommendation!B$2:B$6) -> Guidance | N125: 59 | O125: {=_xlfn.IFS(Table1[[#This Row],[Duration]]<90,"Short",Table1[[#This Row],[Duration]]<180,"Medium",Table1[[#This Row],[Duration]]<=240,"Long",TRUE,"Seasons")} -> Short | P125: Action & Adventure, Anime Features, Children & Family Movies
A126: s282 | B126: Movie | C126: Brother Jekwu | D126: Charles Uwagbai | E126: Mike Ezuruonye, Juliet Ochienge, Angela Okorie, Huddah Monroe, Catherine Kamau, Naomi Mburu, Derrick Aduwo, Chris Kamau, Abubakar Salum, Celebrity Landlord | F126: Nigeria | G126: August 11, 2021 | H126: 2021 | I126: 2016 | J126: =YEAR(TODAY())-Table1[[#This Row],[Release_year]] -> 10 | K126: TV-14 | L126: =_xlfn.XLOOKUP(Table1[[#This Row],[Rating]],Ratings!A$2:A$15,Ratings!B$2:B$15) -> Teen | M126: =_xlfn.XLOOKUP(Table1[[#This Row],[Rating Category]],Recommendation!A$2:A$6,Recommendation!B$2:B$6) -> Guidance | N126: 101 | O126: {=_xlfn.IFS(Table1[[#This Row],[Duration]]<90,"Short",Table1[[#This Row],[Duration]]<180,"Medium",Table1[[#This Row],[Duration]]<=240,"Long",TRUE,"Seasons")} -> Medium | P126: Comedies, International Movies
A127: s283 | B127: Movie | C127: La diosa del asfalto | D127: Julin Hernndez | E127: Ximena Romo, Mabel Cadena, Alejandra Herrera, Nelly Gonzlez, Samantha Orozco, Axel Arenas, Esteban Caicedo, Paulina Goto, Raquel Robles, Baby Btiz, Pascacio Lpez, Jun Carlos Torres, Javier Olivn, Claudia Lobo, Giovanna Zacaras | F127: Mexico | G127: August 11, 2021 | H127: 2021 | I127: 2020 | J127: =YEAR(TODAY())-Table1[[#This Row],[Release_year]] -> 6 | K127: TV-MA | L127: =_xlfn.XLOOKUP(Table1[[#This Row],[Rating]],Ratings!A$2:A$15,Ratings!B$2:B$15) -> Adult | M127: =_xlfn.XLOOKUP(Table1[[#This Row],[Rating Category]],Recommendation!A$2:A$6,Recommendation!B$2:B$6) -> Restricted | N127: 127 | O127: {=_xlfn.IFS(Table1[[#This Row],[Duration]]<90,"Short",Table1[[#This Row],[Duration]]<180,"Medium",Table1[[#This Row],[Duration]]<=240,"Long",TRUE,"Seasons")} -> Medium | P127: Dramas, Independent Movies, International Movies
A128: s285 | B128: Movie | C128: The Kissing Booth 3 | D128: Vince Marcello | E128: Joey King, Joel Courtney, Jacob Elordi, Molly Ringwald, Taylor Zakhar Perez, Maisie Richardson-Sellers, Meganne Young, Stephen Jennings | F128: United Kingdom, United States | G128: August 11, 2021 | H128: 2021 | I128: 2021 | J128: =YEAR(TODAY())-Table1[[#This Row],[Release_year]] -> 5 | K128: TV-14 | L128: =_xlfn.XLOOKUP(Table1[[#This Row],[Rating]],Ratings!A$2:A$15,Ratings!B$2:B$15) -> Teen | M128: =_xlfn.XLOOKUP(Table1[[#This Row],[Rating Category]],Recommendation!A$2:A$6,Recommendation!B$2:B$6) -> Guidance | N128: 114 | O128: {=_xlfn.IFS(Table1[[#This Row],[Duration]]<90,"Short",Table1[[#This Row],[Duration]]<180,"Medium",Table1[[#This Row],[Duration]]<=240,"Long",TRUE,"Seasons")} -> Medium | P128: Comedies, Romantic Movies
A129: s286 | B129: Movie | C129: The Railway Man | D129: Jonathan Teplitzky | E129: Colin Firth, Nicole Kidman, Jeremy Irvine, Stellan Skarsgrd, Sam Reid, Hiroyuki Sanada, Michael MacKenzie, Tom Stokes | F129: Switzerland, United Kingdom, Australia | G129: August 11, 2021 | H129: 2021 | I129: 2013 | J129: =YEAR(TODAY())-Table1[[#This Row],[Release_year]] -> 13 | K129: R | L129: =_xlfn.XLOOKUP(Table1[[#This Row],[Rating]],Ratings!A$2:A$15,Ratings!B$2:B$15) -> Adult | M129: =_xlfn.XLOOKUP(Table1[[#This Row],[Rating Category]],Recommendation!A$2:A$6,Recommendation!B$2:B$6) -> Restricted | N129: 108 | O129: {=_xlfn.IFS(Table1[[#This Row],[Duration]]<90,"Short",Table1[[#This Row],[Duration]]<180,"Medium",Table1[[#This Row],[Duration]]<=240,"Long",TRUE,"Seasons")} -> Medium | P129: Dramas, International Movies
A130: s293 | B130: Movie | C130: Quartet | D130: Dustin Hoffman | E130: Maggie Smith, Tom Courtenay, Billy Connolly, Pauline Collins, Michael Gambon, Andrew Sachs, Sheridan Smith, David Ryall, Trevor Peacock, Gwyneth Jones | F130: United Kingdom | G130: August 8, 2021 | H130: 2021 | I130: 2012 | J130: =YEAR(TODAY())-Table1[[#This Row],[Release_year]] -> 14 | K130: PG-13 | L130: =_xlfn.XLOOKUP(Table1[[#This Row],[Rating]],Ratings!A$2:A$15,Ratings!B$2:B$15) -> Teen | M130: =_xlfn.XLOOKUP(Table1[[#This Row],[Rating Category]],Recommendation!A$2:A$6,Recommendation!B$2:B$6) -> Guidance | N130: 98 | O130: {=_xlfn.IFS(Table1[[#This Row],[Duration]]<90,"Short",Table1[[#This Row],[Duration]]<180,"Medium",Table1[[#This Row],[Duration]]<=240,"Long",TRUE,"Seasons")} -> Medium | P130: Comedies, Dramas, Independent Movies
A131: s294 | B131: Movie | C131: Slay | D131: Adze Ugah | E131: Enhle Mbali, Ramsey Nouah, Dawn Thandeka Kang, Idris Sultan, Tumi Morake, Trevor Gumbi, Lillian Dube, Kaly Bossy Asante, Shaleen Surtie, Fabian Lojege | F131: South Africa | G131: August 8, 2021 | H131: 2021 | I131: 2021 | J131: =YEAR(TODAY())-Table1[[#This Row],[Release_year]] -> 5 | K131: TV-MA | L131: =_xlfn.XLOOKUP(Table1[[#This Row],[Rating]],Ratings!A$2:A$15,Ratings!B$2:B$15) -> Adult | M131: =_xlfn.XLOOKUP(Table1[[#This Row],[Rating Category]],Recommendation!A$2:A$6,Recommendation!B$2:B$6) -> Restricted | N131: 86 | O131: {=_xlfn.IFS(Table1[[#This Row],[Duration]]<90,"Short",Table1[[#This Row],[Duration]]<180,"Medium",Table1[[#This Row],[Duration]]<=240,"Long",TRUE,"Seasons")} -> Short | P131: Comedies, International Movies, Romantic Movies
...

Sheet Recommendation
A1: Category | B1: Recommendation
A2: Kids | B2: Safe
A3: Family | B3: Guidance
A4: Teen | B4: Guidance
A5: Adult | B5: Restricted
A6: Not Rated | B6: Guidance

Sheet Ratings
A1: Ratings | B1: Rating Category
A2: TV-Y | B2: Kids
A3: TV-G | B3: Family
A4: TV-14 | B4: Teen
A5: TV-MA | B5: Adult
A6: PG | B6: Family
A7: PG-13 | B7: Teen
A8: R | B8: Adult
A9: TV-PG | B9: Family
A10: G | B10: Family
A11: NC-17 | B11: Adult
A12: NR | B12: Not Rated
... A15: UR | B15: Not Rated
